Workbook

Sheet Инструкция
A1: Калькулятор юнит-экономики — Wildberries (Китай, FBS / трансграница)
A2: Все суммы — в юанях (CNY), это валюта договора (п. 5.12 оферты). Курс — только для справочного отображения витрины в ₽.
A5: КАК ПОЛЬЗОВАТЬСЯ
A6: 1. | D6: Откройте лист «Калькулятор». Заполняйте только ячейки, выделенные жёлтой заливкой и синим шрифтом — это входные данные.
A7: 2. | D7: Чёрный шрифт — расчётные ячейки (формулы). Их менять не нужно — они пересчитываются автоматически.
A8: 3. | D8: Проценты вводите как есть в поле (напр. 20% → введите 20 и знак %, либо 0,2). Итог — блок 13 внизу листа.
A9: 4. | D9: Лист «Сценарии» показывает, как меняется маржа при разной доле выкупа и ставке комиссии — на основе данных «Калькулятора».
A11: ЦВЕТОВАЯ ЛЕГЕНДА
A12: Синий шрифт / жёлтая заливка | D12: Ввод пользователя (заполнить своими цифрами)
A13: Чёрный шрифт | D13: Формула (не трогать)
A14: Зелёный шрифт | D14: Ссылка на другой лист
A16: МОДЕЛЬ ЗАТРАТ — привязка к пунктам оферты
A17: Комиссия ВБ | D17: В = Рц × кВВ (мин. 1%). Пп. 6.2, 12.2. Ставка кВВ — из тарифов, п. 6.6.
A18: Фин. издержки (эквайринг+конвертация) | D18: Берутся СВЕРХ комиссии, отдельной строкой. П. 12.2.1 (обр. сила с 01.04.2024).
A19: Логистика прямая | D19: РФ-формула 8 + (Б−1)×2 CNY (п. 13.1.11.1) ИЛИ весовая Ру = ФВз×ТФВз + Тз (п. 13.1.12). Из Китая — тариф из таблицы складов КНР.
A20: Коэффициент Клх | D20: Множитель к логистике и хранению, зависит от точности габаритов (СоА): 1 / 1,5 / 2 / 3 / 4. П. 13.3. Нет габаритов → ×25 (п. 13.3.15).
A21: Хранение | D21: Тариф за каждый день хранения × Клх. Пп. 5.12.3, 13.2.
A22: Возвраты | D22: Обратная логистика 1× (возврат покупателем / не вывезен из КНР) или 2× (не прошёл таможню РФ). П. 13.1.14.
A23: Утилизация | D23: Тариф за единицу при утиле невозвращаемого товара. П. 13.4.
A24: Продвижение (ДРР) | D24: WB.Продвижение: CPM/CPO/CPC. П. 14. В модели — % от выручки.
A25: Штрафы | D25: Лимит по обороту: 5% / 7,5% / 10% и т.д. П. 9.9.6. В модели — резерв на единицу.
A26: НДС | D26: Цена включает косвенные налоги (п. 5.2). Ставка до 22% (п. 9.2.3). Неплательщик НДС → 0 (п. 6.8).
A27: Выплата | D27: Порог 10 000 CNY/нед., цикл: неделя + 7 дн. + 10 раб. дн. Пп. 5.5–5.7. (Влияет на оборотку, не на маржу.)
A29: ВАЖНО

Sheet Калькулятор
A1: КАЛЬКУЛЯТОР ЮНИТ-ЭКОНОМИКИ (на 1 единицу, CNY)
A2: Жёлтые ячейки (синий шрифт) = ввод. Чёрные = формулы. Значения по умолчанию — пример (Китай→РФ).
A3: Показатель | B3: Значение | C3: Ед. | D3: Пункт оферты / примечание
A4: 1. ВАЛЮТА И КУРС (справочно — витрина в ₽)
A5: Курс ЦБ, CNY→RUB | B5: 12 | C5: ₽/¥ | D5: Официальный курс ЦБ РФ
A6: Наценка «Курс ВБ» (не более 10%) | B6: 0.08 | C6: % | D6: п. 5.1.1 — не выше курса ЦБ +10%
A7: Курс ВБ (расчётный) | B7: =B5*(1+B6) | C7: ₽/¥ | D7: п. 5.1.1
A8: 2. ЦЕНА И СЕБЕСТОИМОСТЬ
A9: Розничная цена Рц (в юанях) | B9: 150 | C9: CNY | D9: п. 5.1 — задаётся в юанях
A10: Цена на витрине (₽, справочно) | B10: =B9*B7 | C10: ₽ | D10: п. 5.1.1
A11: Себестоимость закупки товара | B11: 45 | C11: CNY | D11: Ваши данные (закупка/производство)
A12: 3. КОМИССИЯ ВБ
A13: Ставка комиссии кВВ | B13: 0.2 | C13: % | D13: п. 6.6 — из тарифов категории
A14: Применяемая кВВ (мин. 1%) | B14: =MAX(B13,0.01) | C14: % | D14: п. 12.2 — если < 1%, считается 1%
A15: Комиссия ВБ = Рц × кВВ | B15: =B9*B14 | C15: CNY | D15: п. 12.2: В = Рц×кВВ − И
A16: 4. ФИН. ИЗДЕРЖКИ: эквайринг + конвертация (СВЕРХ комиссии)
A17: Ставка фин. издержек, % от Рц | B17: 0.03 | C17: % | D17: п. 12.2.1 — возмещаются доп. (п. 6.3)
A18: Фин. издержки = Рц × ставка | B18: =B9*B17 | C18: CNY | D18: п. 12.2.1
A19: 5. ГАБАРИТЫ И ВЕС УПАКОВКИ
A20: Длина | B20: 30 | C20: см | D20: Габарит с упаковкой
A21: Ширина | B21: 25 | C21: см | D21: Габарит с упаковкой
A22: Высота | B22: 5 | C22: см | D22: Габарит с упаковкой
A23: Вес брутто | B23: 0.4 | C23: кг | D23: Макс. 20 кг для международки (п. 13.1.4)
A24: Объём упаковки Б (округл. вверх, мин. 1) | B24: =MAX(1,CEILING(B20*B21*B22/1000,1)) | C24: л | D24: п. 13.1.11.1
A25: Физ. вес округл. до 100 г | B25: =CEILING(B23,0.1) | C25: кг | D25: п. 13.1.12
A26: 6. КОЭФФИЦИЕНТ ЛОГИСТИКИ И ХРАНЕНИЯ (Клх)
A27: Среднее отклонение габаритов (СоА) | B27: 0.08 | C27: % | D27: Факт vs карточка. п. 13.3.8
A28: Клх (авто по таблице) | B28: =IF(B27<=0.1,1,IF(B27<=0.25,1.5,IF(B27<=0.5,2,IF(B27<=1,3,4)))) | C28: × | D28: п. 13.3.7: ≤10%→1; ≤25%→1,5; ≤50%→2; ≤100%→3; >100%→4
A29: ⚠ Если габариты в карточке НЕ указаны — коэффициент 25 (п. 13.3.15). Впишите 25 в Клх вручную.
A30: 7. ЛОГИСТИКА (прямая доставка)
A31: Метод расчёта (1 = формула РФ, 2 = вес/Китай) | B31: 1 | C31: 1/2 | D31: 1: 8+(Б−1)×2 (внутри РФ, п.13.1.11.1); 2: весовой Ру (п.13.1.12) или тариф склада КНР
A32: Лог. по формуле РФ = 8 + (Б−1)×2 | B32: =8+(B24-1)*2 | C32: CNY | D32: п. 13.1.11.1: А=8, В=2 CNY
A33: Тариф за заказ (Тз) | B33: 5 | C33: CNY | D33: п. 13.1.12 / таблица складов КНР
A34: Тариф за вес (ТФВз), за 100 г | B34: 1 | C34: CNY | D34: п. 13.1.12
A35: Лог. весовая Ру = вес×ТФВз + Тз | B35: =B25*10*B34+B33 | C35: CNY | D35: п. 13.1.12
A36: Логистика прямая (с учётом Клх) | B36: =IF(B31=1,B32,B35)*B28 | C36: CNY | D36: Выбранный метод × Клх. п. 13.1, 13.3.6
A37: 8. ХРАНЕНИЕ
A38: Тариф хранения за 1 день | B38: 0.1 | C38: CNY/дн | D38: п. 13.2, тарифы п. 6.6
A39: Среднее число дней хранения | B39: 20 | C39: дн | D39: Оценка оборачиваемости
A40: Хранение (с учётом Клх) | B40: =B38*B39*B28 | C40: CNY | D40: п. 13.2, 13.3.6
...

Sheet Сценарии
A1: СЦЕНАРИИ И ЧУВСТВИТЕЛЬНОСТЬ
A2: Значения тянутся с листа «Калькулятор». Меняйте входные данные там — таблицы пересчитаются.
A4: Параметры (из «Калькулятора»)
A5: Розничная цена Рц | B5: =Калькулятор!B9
A6: Себестоимость | B6: =Калькулятор!B11
A7: Фин. издержки | B7: =Калькулятор!B18
A8: Логистика прямая (с Клх) | B8: =Калькулятор!B36
A9: Множитель обр. логистики | B9: =Калькулятор!B44
A10: Доля возвратов в утиль | B10: =Калькулятор!B45
A11: Тариф утилизации | B11: =Калькулятор!B47
A12: Хранение | B12: =Калькулятор!B40
A13: Продвижение | B13: =Калькулятор!B50
A14: НДС | B14: =Калькулятор!B54
A15: Резерв штрафы | B15: =Калькулятор!B55
A16: Базовая ставка кВВ | B16: =Калькулятор!B14
A18: Чувствительность к доле ВЫКУПА (комиссия — базовая)
A19: Доля выкупа → | C19: 0.4 | D19: 0.5 | E19: 0.6 | F19: 0.7 | G19: 0.8 | H19: 0.9 | I19: 1
A20: Прибыль, CNY | C20: =$B$5-$B$6-$B$5*$B$16-$B$7-IF(C$19=0,0,$B$8/C$19)-$B$8*$B$9*IF(C$19=0,0,(1-C$19)/C$19)-$B$6*IF(C$19=0,0,(1-C$19)/C$19)*$B$10-$B$11*IF(C$19=0,0,(1-C$19)/C$19)*$B$10-$B$12-$B$13-$B$14-$B$15 | D20: =$B$5-$B$6-$B$5*$B$16-$B$7-IF(D$19=0,0,$B$8/D$19)-$B$8*$B$9*IF(D$19=0,0,(1-D$19)/D$19)-$B$6*IF(D$19=0,0,(1-D$19)/D$19)*$B$10-$B$11*IF(D$19=0,0,(1-D$19)/D$19)*$B$10-$B$12-$B$13-$B$14-$B$15 | E20: =$B$5-$B$6-$B$5*$B$16-$B$7-IF(E$19=0,0,$B$8/E$19)-$B$8*$B$9*IF(E$19=0,0,(1-E$19)/E$19)-$B$6*IF(E$19=0,0,(1-E$19)/E$19)*$B$10-$B$11*IF(E$19=0,0,(1-E$19)/E$19)*$B$10-$B$12-$B$13-$B$14-$B$15 | F20: =$B$5-$B$6-$B$5*$B$16-$B$7-IF(F$19=0,0,$B$8/F$19)-$B$8*$B$9*IF(F$19=0,0,(1-F$19)/F$19)-$B$6*IF(F$19=0,0,(1-F$19)/F$19)*$B$10-$B$11*IF(F$19=0,0,(1-F$19)/F$19)*$B$10-$B$12-$B$13-$B$14-$B$15 | G20: =$B$5-$B$6-$B$5*$B$16-$B$7-IF(G$19=0,0,$B$8/G$19)-$B$8*$B$9*IF(G$19=0,0,(1-G$19)/G$19)-$B$6*IF(G$19=0,0,(1-G$19)/G$19)*$B$10-$B$11*IF(G$19=0,0,(1-G$19)/G$19)*$B$10-$B$12-$B$13-$B$14-$B$15 | H20: =$B$5-$B$6-$B$5*$B$16-$B$7-IF(H$19=0,0,$B$8/H$19)-$B$8*$B$9*IF(H$19=0,0,(1-H$19)/H$19)-$B$6*IF(H$19=0,0,(1-H$19)/H$19)*$B$10-$B$11*IF(H$19=0,0,(1-H$19)/H$19)*$B$10-$B$12-$B$13-$B$14-$B$15 | I20: =$B$5-$B$6-$B$5*$B$16-$B$7-IF(I$19=0,0,$B$8/I$19)-$B$8*$B$9*IF(I$19=0,0,(1-I$19)/I$19)-$B$6*IF(I$19=0,0,(1-I$19)/I$19)*$B$10-$B$11*IF(I$19=0,0,(1-I$19)/I$19)*$B$10-$B$12-$B$13-$B$14-$B$15
A21: Маржа, % | C21: =IF($B$5=0,0,C20/$B$5) | D21: =IF($B$5=0,0,D20/$B$5) | E21: =IF($B$5=0,0,E20/$B$5) | F21: =IF($B$5=0,0,F20/$B$5) | G21: =IF($B$5=0,0,G20/$B$5) | H21: =IF($B$5=0,0,H20/$B$5) | I21: =IF($B$5=0,0,I20/$B$5)
A24: Маржа, %: ВЫКУП (строки) × КОМИССИЯ кВВ (столбцы)
A25: выкуп ↓ / кВВ → | B25: 0.1 | C25: 0.15 | D25: 0.2 | E25: 0.25 | F25: 0.3
A26: 0.5 | B26: =IF($B$5=0,0,($B$5-$B$6-$B$5*B$25-$B$7-IF($A26=0,0,$B$8/$A26)-$B$8*$B$9*IF($A26=0,0,(1-$A26)/$A26)-$B$6*IF($A26=0,0,(1-$A26)/$A26)*$B$10-$B$11*IF($A26=0,0,(1-$A26)/$A26)*$B$10-$B$12-$B$13-$B$14-$B$15)/$B$5) | C26: =IF($B$5=0,0,($B$5-$B$6-$B$5*C$25-$B$7-IF($A26=0,0,$B$8/$A26)-$B$8*$B$9*IF($A26=0,0,(1-$A26)/$A26)-$B$6*IF($A26=0,0,(1-$A26)/$A26)*$B$10-$B$11*IF($A26=0,0,(1-$A26)/$A26)*$B$10-$B$12-$B$13-$B$14-$B$15)/$B$5) | D26: =IF($B$5=0,0,($B$5-$B$6-$B$5*D$25-$B$7-IF($A26=0,0,$B$8/$A26)-$B$8*$B$9*IF($A26=0,0,(1-$A26)/$A26)-$B$6*IF($A26=0,0,(1-$A26)/$A26)*$B$10-$B$11*IF($A26=0,0,(1-$A26)/$A26)*$B$10-$B$12-$B$13-$B$14-$B$15)/$B$5) | E26: =IF($B$5=0,0,($B$5-$B$6-$B$5*E$25-$B$7-IF($A26=0,0,$B$8/$A26)-$B$8*$B$9*IF($A26=0,0,(1-$A26)/$A26)-$B$6*IF($A26=0,0,(1-$A26)/$A26)*$B$10-$B$11*IF($A26=0,0,(1-$A26)/$A26)*$B$10-$B$12-$B$13-$B$14-$B$15)/$B$5) | F26: =IF($B$5=0,0,($B$5-$B$6-$B$5*F$25-$B$7-IF($A26=0,0,$B$8/$A26)-$B$8*$B$9*IF($A26=0,0,(1-$A26)/$A26)-$B$6*IF($A26=0,0,(1-$A26)/$A26)*$B$10-$B$11*IF($A26=0,0,(1-$A26)/$A26)*$B$10-$B$12-$B$13-$B$14-$B$15)/$B$5)
A27: 0.6 | B27: =IF($B$5=0,0,($B$5-$B$6-$B$5*B$25-$B$7-IF($A27=0,0,$B$8/$A27)-$B$8*$B$9*IF($A27=0,0,(1-$A27)/$A27)-$B$6*IF($A27=0,0,(1-$A27)/$A27)*$B$10-$B$11*IF($A27=0,0,(1-$A27)/$A27)*$B$10-$B$12-$B$13-$B$14-$B$15)/$B$5) | C27: =IF($B$5=0,0,($B$5-$B$6-$B$5*C$25-$B$7-IF($A27=0,0,$B$8/$A27)-$B$8*$B$9*IF($A27=0,0,(1-$A27)/$A27)-$B$6*IF($A27=0,0,(1-$A27)/$A27)*$B$10-$B$11*IF($A27=0,0,(1-$A27)/$A27)*$B$10-$B$12-$B$13-$B$14-$B$15)/$B$5) | D27: =IF($B$5=0,0,($B$5-$B$6-$B$5*D$25-$B$7-IF($A27=0,0,$B$8/$A27)-$B$8*$B$9*IF($A27=0,0,(1-$A27)/$A27)-$B$6*IF($A27=0,0,(1-$A27)/$A27)*$B$10-$B$11*IF($A27=0,0,(1-$A27)/$A27)*$B$10-$B$12-$B$13-$B$14-$B$15)/$B$5) | E27: =IF($B$5=0,0,($B$5-$B$6-$B$5*E$25-$B$7-IF($A27=0,0,$B$8/$A27)-$B$8*$B$9*IF($A27=0,0,(1-$A27)/$A27)-$B$6*IF($A27=0,0,(1-$A27)/$A27)*$B$10-$B$11*IF($A27=0,0,(1-$A27)/$A27)*$B$10-$B$12-$B$13-$B$14-$B$15)/$B$5) | F27: =IF($B$5=0,0,($B$5-$B$6-$B$5*F$25-$B$7-IF($A27=0,0,$B$8/$A27)-$B$8*$B$9*IF($A27=0,0,(1-$A27)/$A27)-$B$6*IF($A27=0,0,(1-$A27)/$A27)*$B$10-$B$11*IF($A27=0,0,(1-$A27)/$A27)*$B$10-$B$12-$B$13-$B$14-$B$15)/$B$5)
A28: 0.7 | B28: =IF($B$5=0,0,($B$5-$B$6-$B$5*B$25-$B$7-IF($A28=0,0,$B$8/$A28)-$B$8*$B$9*IF($A28=0,0,(1-$A28)/$A28)-$B$6*IF($A28=0,0,(1-$A28)/$A28)*$B$10-$B$11*IF($A28=0,0,(1-$A28)/$A28)*$B$10-$B$12-$B$13-$B$14-$B$15)/$B$5) | C28: =IF($B$5=0,0,($B$5-$B$6-$B$5*C$25-$B$7-IF($A28=0,0,$B$8/$A28)-$B$8*$B$9*IF($A28=0,0,(1-$A28)/$A28)-$B$6*IF($A28=0,0,(1-$A28)/$A28)*$B$10-$B$11*IF($A28=0,0,(1-$A28)/$A28)*$B$10-$B$12-$B$13-$B$14-$B$15)/$B$5) | D28: =IF($B$5=0,0,($B$5-$B$6-$B$5*D$25-$B$7-IF($A28=0,0,$B$8/$A28)-$B$8*$B$9*IF($A28=0,0,(1-$A28)/$A28)-$B$6*IF($A28=0,0,(1-$A28)/$A28)*$B$10-$B$11*IF($A28=0,0,(1-$A28)/$A28)*$B$10-$B$12-$B$13-$B$14-$B$15)/$B$5) | E28: =IF($B$5=0,0,($B$5-$B$6-$B$5*E$25-$B$7-IF($A28=0,0,$B$8/$A28)-$B$8*$B$9*IF($A28=0,0,(1-$A28)/$A28)-$B$6*IF($A28=0,0,(1-$A28)/$A28)*$B$10-$B$11*IF($A28=0,0,(1-$A28)/$A28)*$B$10-$B$12-$B$13-$B$14-$B$15)/$B$5) | F28: =IF($B$5=0,0,($B$5-$B$6-$B$5*F$25-$B$7-IF($A28=0,0,$B$8/$A28)-$B$8*$B$9*IF($A28=0,0,(1-$A28)/$A28)-$B$6*IF($A28=0,0,(1-$A28)/$A28)*$B$10-$B$11*IF($A28=0,0,(1-$A28)/$A28)*$B$10-$B$12-$B$13-$B$14-$B$15)/$B$5)
A29: 0.8 | B29: =IF($B$5=0,0,($B$5-$B$6-$B$5*B$25-$B$7-IF($A29=0,0,$B$8/$A29)-$B$8*$B$9*IF($A29=0,0,(1-$A29)/$A29)-$B$6*IF($A29=0,0,(1-$A29)/$A29)*$B$10-$B$11*IF($A29=0,0,(1-$A29)/$A29)*$B$10-$B$12-$B$13-$B$14-$B$15)/$B$5) | C29: =IF($B$5=0,0,($B$5-$B$6-$B$5*C$25-$B$7-IF($A29=0,0,$B$8/$A29)-$B$8*$B$9*IF($A29=0,0,(1-$A29)/$A29)-$B$6*IF($A29=0,0,(1-$A29)/$A29)*$B$10-$B$11*IF($A29=0,0,(1-$A29)/$A29)*$B$10-$B$12-$B$13-$B$14-$B$15)/$B$5) | D29: =IF($B$5=0,0,($B$5-$B$6-$B$5*D$25-$B$7-IF($A29=0,0,$B$8/$A29)-$B$8*$B$9*IF($A29=0,0,(1-$A29)/$A29)-$B$6*IF($A29=0,0,(1-$A29)/$A29)*$B$10-$B$11*IF($A29=0,0,(1-$A29)/$A29)*$B$10-$B$12-$B$13-$B$14-$B$15)/$B$5) | E29: =IF($B$5=0,0,($B$5-$B$6-$B$5*E$25-$B$7-IF($A29=0,0,$B$8/$A29)-$B$8*$B$9*IF($A29=0,0,(1-$A29)/$A29)-$B$6*IF($A29=0,0,(1-$A29)/$A29)*$B$10-$B$11*IF($A29=0,0,(1-$A29)/$A29)*$B$10-$B$12-$B$13-$B$14-$B$15)/$B$5) | F29: =IF($B$5=0,0,($B$5-$B$6-$B$5*F$25-$B$7-IF($A29=0,0,$B$8/$A29)-$B$8*$B$9*IF($A29=0,0,(1-$A29)/$A29)-$B$6*IF($A29=0,0,(1-$A29)/$A29)*$B$10-$B$11*IF($A29=0,0,(1-$A29)/$A29)*$B$10-$B$12-$B$13-$B$14-$B$15)/$B$5)
A30: 0.9 | B30: =IF($B$5=0,0,($B$5-$B$6-$B$5*B$25-$B$7-IF($A30=0,0,$B$8/$A30)-$B$8*$B$9*IF($A30=0,0,(1-$A30)/$A30)-$B$6*IF($A30=0,0,(1-$A30)/$A30)*$B$10-$B$11*IF($A30=0,0,(1-$A30)/$A30)*$B$10-$B$12-$B$13-$B$14-$B$15)/$B$5) | C30: =IF($B$5=0,0,($B$5-$B$6-$B$5*C$25-$B$7-IF($A30=0,0,$B$8/$A30)-$B$8*$B$9*IF($A30=0,0,(1-$A30)/$A30)-$B$6*IF($A30=0,0,(1-$A30)/$A30)*$B$10-$B$11*IF($A30=0,0,(1-$A30)/$A30)*$B$10-$B$12-$B$13-$B$14-$B$15)/$B$5) | D30: =IF($B$5=0,0,($B$5-$B$6-$B$5*D$25-$B$7-IF($A30=0,0,$B$8/$A30)-$B$8*$B$9*IF($A30=0,0,(1-$A30)/$A30)-$B$6*IF($A30=0,0,(1-$A30)/$A30)*$B$10-$B$11*IF($A30=0,0,(1-$A30)/$A30)*$B$10-$B$12-$B$13-$B$14-$B$15)/$B$5) | E30: =IF($B$5=0,0,($B$5-$B$6-$B$5*E$25-$B$7-IF($A30=0,0,$B$8/$A30)-$B$8*$B$9*IF($A30=0,0,(1-$A30)/$A30)-$B$6*IF($A30=0,0,(1-$A30)/$A30)*$B$10-$B$11*IF($A30=0,0,(1-$A30)/$A30)*$B$10-$B$12-$B$13-$B$14-$B$15)/$B$5) | F30: =IF($B$5=0,0,($B$5-$B$6-$B$5*F$25-$B$7-IF($A30=0,0,$B$8/$A30)-$B$8*$B$9*IF($A30=0,0,(1-$A30)/$A30)-$B$6*IF($A30=0,0,(1-$A30)/$A30)*$B$10-$B$11*IF($A30=0,0,(1-$A30)/$A30)*$B$10-$B$12-$B$13-$B$14-$B$15)/$B$5)
A31: 1 | B31: =IF($B$5=0,0,($B$5-$B$6-$B$5*B$25-$B$7-IF($A31=0,0,$B$8/$A31)-$B$8*$B$9*IF($A31=0,0,(1-$A31)/$A31)-$B$6*IF($A31=0,0,(1-$A31)/$A31)*$B$10-$B$11*IF($A31=0,0,(1-$A31)/$A31)*$B$10-$B$12-$B$13-$B$14-$B$15)/$B$5) | C31: =IF($B$5=0,0,($B$5-$B$6-$B$5*C$25-$B$7-IF($A31=0,0,$B$8/$A31)-$B$8*$B$9*IF($A31=0,0,(1-$A31)/$A31)-$B$6*IF($A31=0,0,(1-$A31)/$A31)*$B$10-$B$11*IF($A31=0,0,(1-$A31)/$A31)*$B$10-$B$12-$B$13-$B$14-$B$15)/$B$5) | D31: =IF($B$5=0,0,($B$5-$B$6-$B$5*D$25-$B$7-IF($A31=0,0,$B$8/$A31)-$B$8*$B$9*IF($A31=0,0,(1-$A31)/$A31)-$B$6*IF($A31=0,0,(1-$A31)/$A31)*$B$10-$B$11*IF($A31=0,0,(1-$A31)/$A31)*$B$10-$B$12-$B$13-$B$14-$B$15)/$B$5) | E31: =IF($B$5=0,0,($B$5-$B$6-$B$5*E$25-$B$7-IF($A31=0,0,$B$8/$A31)-$B$8*$B$9*IF($A31=0,0,(1-$A31)/$A31)-$B$6*IF($A31=0,0,(1-$A31)/$A31)*$B$10-$B$11*IF($A31=0,0,(1-$A31)/$A31)*$B$10-$B$12-$B$13-$B$14-$B$15)/$B$5) | F31: =IF($B$5=0,0,($B$5-$B$6-$B$5*F$25-$B$7-IF($A31=0,0,$B$8/$A31)-$B$8*$B$9*IF($A31=0,0,(1-$A31)/$A31)-$B$6*IF($A31=0,0,(1-$A31)/$A31)*$B$10-$B$11*IF($A31=0,0,(1-$A31)/$A31)*$B$10-$B$12-$B$13-$B$14-$B$15)/$B$5)
A33: Положительная маржа — прибыльно; отрицательная — убыток при данных условиях.
